{
 "cells": [
  {
   "cell_type": "code",
   "execution_count": 1,
   "id": "6f2c56a3",
   "metadata": {},
   "outputs": [
    {
     "name": "stdout",
     "output_type": "stream",
     "text": [
      "Collecting s3fs\n",
      "  Downloading s3fs-2023.3.0-py3-none-any.whl (27 kB)\n",
      "Collecting aiobotocore~=2.4.2\n",
      "  Downloading aiobotocore-2.4.2-py3-none-any.whl (66 kB)\n",
      "\u001b[2K     \u001b[90m━━━━━━━━━━━━━━━━━━━━━━━━━━━━━━━━━━━━━━━━\u001b[0m \u001b[32m66.8/66.8 kB\u001b[0m \u001b[31m4.6 MB/s\u001b[0m eta \u001b[36m0:00:00\u001b[0m\n",
      "\u001b[?25hCollecting aiohttp!=4.0.0a0,!=4.0.0a1\n",
      "  Downloading aiohttp-3.8.4-cp310-cp310-macosx_10_9_x86_64.whl (358 kB)\n",
      "\u001b[2K     \u001b[90m━━━━━━━━━━━━━━━━━━━━━━━━━━━━━━━━━━━━━━━\u001b[0m \u001b[32m358.1/358.1 kB\u001b[0m \u001b[31m4.1 MB/s\u001b[0m eta \u001b[36m0:00:00\u001b[0ma \u001b[36m0:00:01\u001b[0m\n",
      "\u001b[?25hCollecting fsspec==2023.3.0\n",
      "  Downloading fsspec-2023.3.0-py3-none-any.whl (145 kB)\n",
      "\u001b[2K     \u001b[90m━━━━━━━━━━━━━━━━━━━━━━━━━━━━━━━━━━━━━━\u001b[0m \u001b[32m145.4/145.4 kB\u001b[0m \u001b[31m30.7 MB/s\u001b[0m eta \u001b[36m0:00:00\u001b[0m\n",
      "\u001b[?25hCollecting aioitertools>=0.5.1\n",
      "  Downloading aioitertools-0.11.0-py3-none-any.whl (23 kB)\n",
      "Requirement already satisfied: wrapt>=1.10.10 in /Users/asraahmed/anaconda3/lib/python3.10/site-packages (from aiobotocore~=2.4.2->s3fs) (1.14.1)\n",
      "Collecting botocore<1.27.60,>=1.27.59\n",
      "  Downloading botocore-1.27.59-py3-none-any.whl (9.1 MB)\n",
      "\u001b[2K     \u001b[90m━━━━━━━━━━━━━━━━━━━━━━━━━━━━━━━━━━━━━━━━\u001b[0m \u001b[32m9.1/9.1 MB\u001b[0m \u001b[31m40.4 MB/s\u001b[0m eta \u001b[36m0:00:00\u001b[0m00:01\u001b[0m00:01\u001b[0m\n",
      "\u001b[?25hCollecting frozenlist>=1.1.1\n",
      "  Downloading frozenlist-1.3.3-cp310-cp310-macosx_10_9_x86_64.whl (35 kB)\n",
      "Collecting async-timeout<5.0,>=4.0.0a3\n",
      "  Using cached async_timeout-4.0.2-py3-none-any.whl (5.8 kB)\n",
      "Collecting yarl<2.0,>=1.0\n",
      "  Downloading yarl-1.8.2-cp310-cp310-macosx_10_9_x86_64.whl (61 kB)\n",
      "\u001b[2K     \u001b[90m━━━━━━━━━━━━━━━━━━━━━━━━━━━━━━━━━━━━━━━━\u001b[0m \u001b[32m61.0/61.0 kB\u001b[0m \u001b[31m11.6 MB/s\u001b[0m eta \u001b[36m0:00:00\u001b[0m\n",
      "\u001b[?25hCollecting aiosignal>=1.1.2\n",
      "  Downloading aiosignal-1.3.1-py3-none-any.whl (7.6 kB)\n",
      "Collecting multidict<7.0,>=4.5\n",
      "  Downloading multidict-6.0.4-cp310-cp310-macosx_10_9_x86_64.whl (29 kB)\n",
      "Requirement already satisfied: charset-normalizer<4.0,>=2.0 in /Users/asraahmed/anaconda3/lib/python3.10/site-packages (from aiohttp!=4.0.0a0,!=4.0.0a1->s3fs) (2.0.4)\n",
      "Requirement already satisfied: attrs>=17.3.0 in /Users/asraahmed/anaconda3/lib/python3.10/site-packages (from aiohttp!=4.0.0a0,!=4.0.0a1->s3fs) (22.1.0)\n",
      "Requirement already satisfied: urllib3<1.27,>=1.25.4 in /Users/asraahmed/anaconda3/lib/python3.10/site-packages (from botocore<1.27.60,>=1.27.59->aiobotocore~=2.4.2->s3fs) (1.26.14)\n",
      "Requirement already satisfied: jmespath<2.0.0,>=0.7.1 in /Users/asraahmed/anaconda3/lib/python3.10/site-packages (from botocore<1.27.60,>=1.27.59->aiobotocore~=2.4.2->s3fs) (0.10.0)\n",
      "Requirement already satisfied: python-dateutil<3.0.0,>=2.1 in /Users/asraahmed/anaconda3/lib/python3.10/site-packages (from botocore<1.27.60,>=1.27.59->aiobotocore~=2.4.2->s3fs) (2.8.2)\n",
      "Requirement already satisfied: idna>=2.0 in /Users/asraahmed/anaconda3/lib/python3.10/site-packages (from yarl<2.0,>=1.0->aiohttp!=4.0.0a0,!=4.0.0a1->s3fs) (3.4)\n",
      "Requirement already satisfied: six>=1.5 in /Users/asraahmed/anaconda3/lib/python3.10/site-packages (from python-dateutil<3.0.0,>=2.1->botocore<1.27.60,>=1.27.59->aiobotocore~=2.4.2->s3fs) (1.16.0)\n",
      "Installing collected packages: multidict, fsspec, frozenlist, async-timeout, aioitertools, yarl, botocore, aiosignal, aiohttp, aiobotocore, s3fs\n",
      "  Attempting uninstall: fsspec\n",
      "    Found existing installation: fsspec 2022.11.0\n",
      "    Uninstalling fsspec-2022.11.0:\n",
      "      Successfully uninstalled fsspec-2022.11.0\n",
      "Successfully installed aiobotocore-2.4.2 aiohttp-3.8.4 aioitertools-0.11.0 aiosignal-1.3.1 async-timeout-4.0.2 botocore-1.27.59 frozenlist-1.3.3 fsspec-2023.3.0 multidict-6.0.4 s3fs-2023.3.0 yarl-1.8.2\n",
      "Note: you may need to restart the kernel to use updated packages.\n"
     ]
    }
   ],
   "source": [
    "pip install s3fs"
   ]
  },
  {
   "cell_type": "code",
   "execution_count": 1,
   "id": "b6675043",
   "metadata": {},
   "outputs": [],
   "source": [
    "from kafka import KafkaConsumer\n",
    "from time import sleep\n",
    "from json import dumps,loads\n",
    "import json\n",
    "from s3fs import S3FileSystem"
   ]
  },
  {
   "cell_type": "code",
   "execution_count": 2,
   "id": "9eeff3ef",
   "metadata": {},
   "outputs": [],
   "source": [
    "consumer = KafkaConsumer(\n",
    "    'demotest',\n",
    "     bootstrap_servers=['3.137.167.221:9092'], \n",
    "    value_deserializer=lambda x: loads(x.decode('utf-8')))"
   ]
  },
  {
   "cell_type": "code",
   "execution_count": 3,
   "id": "eda5a608",
   "metadata": {},
   "outputs": [],
   "source": [
    "#for c in consumer:\n",
    "#    print(c.value)\n",
    "\n"
   ]
  },
  {
   "cell_type": "code",
   "execution_count": 4,
   "id": "8d60dc6c",
   "metadata": {},
   "outputs": [],
   "source": [
    "s3 = S3FileSystem()"
   ]
  },
  {
   "cell_type": "code",
   "execution_count": 5,
   "id": "0f135e81",
   "metadata": {},
   "outputs": [
    {
     "ename": "EndpointConnectionError",
     "evalue": "Could not connect to the endpoint URL: \"https://asra-test-bucket.s3.ohio.amazonaws.com/stock_market_0.json\"",
     "output_type": "error",
     "traceback": [
      "\u001b[0;31m---------------------------------------------------------------------------\u001b[0m",
      "\u001b[0;31mgaierror\u001b[0m                                  Traceback (most recent call last)",
      "File \u001b[0;32m~/anaconda3/lib/python3.10/site-packages/aiohttp/connector.py:1152\u001b[0m, in \u001b[0;36mTCPConnector._create_direct_connection\u001b[0;34m(self, req, traces, timeout, client_error)\u001b[0m\n\u001b[1;32m   1148\u001b[0m \u001b[38;5;28;01mtry\u001b[39;00m:\n\u001b[1;32m   1149\u001b[0m     \u001b[38;5;66;03m# Cancelling this lookup should not cancel the underlying lookup\u001b[39;00m\n\u001b[1;32m   1150\u001b[0m     \u001b[38;5;66;03m#  or else the cancel event will get broadcast to all the waiters\u001b[39;00m\n\u001b[1;32m   1151\u001b[0m     \u001b[38;5;66;03m#  across all connections.\u001b[39;00m\n\u001b[0;32m-> 1152\u001b[0m     hosts \u001b[38;5;241m=\u001b[39m \u001b[38;5;28;01mawait\u001b[39;00m asyncio\u001b[38;5;241m.\u001b[39mshield(host_resolved)\n\u001b[1;32m   1153\u001b[0m \u001b[38;5;28;01mexcept\u001b[39;00m asyncio\u001b[38;5;241m.\u001b[39mCancelledError:\n",
      "File \u001b[0;32m~/anaconda3/lib/python3.10/site-packages/aiohttp/connector.py:874\u001b[0m, in \u001b[0;36mTCPConnector._resolve_host\u001b[0;34m(self, host, port, traces)\u001b[0m\n\u001b[1;32m    872\u001b[0m         \u001b[38;5;28;01mawait\u001b[39;00m trace\u001b[38;5;241m.\u001b[39msend_dns_resolvehost_start(host)\n\u001b[0;32m--> 874\u001b[0m addrs \u001b[38;5;241m=\u001b[39m \u001b[38;5;28;01mawait\u001b[39;00m \u001b[38;5;28mself\u001b[39m\u001b[38;5;241m.\u001b[39m_resolver\u001b[38;5;241m.\u001b[39mresolve(host, port, family\u001b[38;5;241m=\u001b[39m\u001b[38;5;28mself\u001b[39m\u001b[38;5;241m.\u001b[39m_family)\n\u001b[1;32m    875\u001b[0m \u001b[38;5;28;01mif\u001b[39;00m traces:\n",
      "File \u001b[0;32m~/anaconda3/lib/python3.10/site-packages/aiohttp/resolver.py:33\u001b[0m, in \u001b[0;36mThreadedResolver.resolve\u001b[0;34m(self, hostname, port, family)\u001b[0m\n\u001b[1;32m     30\u001b[0m \u001b[38;5;28;01masync\u001b[39;00m \u001b[38;5;28;01mdef\u001b[39;00m \u001b[38;5;21mresolve\u001b[39m(\n\u001b[1;32m     31\u001b[0m     \u001b[38;5;28mself\u001b[39m, hostname: \u001b[38;5;28mstr\u001b[39m, port: \u001b[38;5;28mint\u001b[39m \u001b[38;5;241m=\u001b[39m \u001b[38;5;241m0\u001b[39m, family: \u001b[38;5;28mint\u001b[39m \u001b[38;5;241m=\u001b[39m socket\u001b[38;5;241m.\u001b[39mAF_INET\n\u001b[1;32m     32\u001b[0m ) \u001b[38;5;241m-\u001b[39m\u001b[38;5;241m>\u001b[39m List[Dict[\u001b[38;5;28mstr\u001b[39m, Any]]:\n\u001b[0;32m---> 33\u001b[0m     infos \u001b[38;5;241m=\u001b[39m \u001b[38;5;28;01mawait\u001b[39;00m \u001b[38;5;28mself\u001b[39m\u001b[38;5;241m.\u001b[39m_loop\u001b[38;5;241m.\u001b[39mgetaddrinfo(\n\u001b[1;32m     34\u001b[0m         hostname,\n\u001b[1;32m     35\u001b[0m         port,\n\u001b[1;32m     36\u001b[0m         \u001b[38;5;28mtype\u001b[39m\u001b[38;5;241m=\u001b[39msocket\u001b[38;5;241m.\u001b[39mSOCK_STREAM,\n\u001b[1;32m     37\u001b[0m         family\u001b[38;5;241m=\u001b[39mfamily,\n\u001b[1;32m     38\u001b[0m         flags\u001b[38;5;241m=\u001b[39msocket\u001b[38;5;241m.\u001b[39mAI_ADDRCONFIG,\n\u001b[1;32m     39\u001b[0m     )\n\u001b[1;32m     41\u001b[0m     hosts \u001b[38;5;241m=\u001b[39m []\n",
      "File \u001b[0;32m~/anaconda3/lib/python3.10/asyncio/base_events.py:863\u001b[0m, in \u001b[0;36mBaseEventLoop.getaddrinfo\u001b[0;34m(self, host, port, family, type, proto, flags)\u001b[0m\n\u001b[1;32m    861\u001b[0m     getaddr_func \u001b[38;5;241m=\u001b[39m socket\u001b[38;5;241m.\u001b[39mgetaddrinfo\n\u001b[0;32m--> 863\u001b[0m \u001b[38;5;28;01mreturn\u001b[39;00m \u001b[38;5;28;01mawait\u001b[39;00m \u001b[38;5;28mself\u001b[39m\u001b[38;5;241m.\u001b[39mrun_in_executor(\n\u001b[1;32m    864\u001b[0m     \u001b[38;5;28;01mNone\u001b[39;00m, getaddr_func, host, port, family, \u001b[38;5;28mtype\u001b[39m, proto, flags)\n",
      "File \u001b[0;32m~/anaconda3/lib/python3.10/concurrent/futures/thread.py:58\u001b[0m, in \u001b[0;36m_WorkItem.run\u001b[0;34m(self)\u001b[0m\n\u001b[1;32m     57\u001b[0m \u001b[38;5;28;01mtry\u001b[39;00m:\n\u001b[0;32m---> 58\u001b[0m     result \u001b[38;5;241m=\u001b[39m \u001b[38;5;28;43mself\u001b[39;49m\u001b[38;5;241;43m.\u001b[39;49m\u001b[43mfn\u001b[49m\u001b[43m(\u001b[49m\u001b[38;5;241;43m*\u001b[39;49m\u001b[38;5;28;43mself\u001b[39;49m\u001b[38;5;241;43m.\u001b[39;49m\u001b[43margs\u001b[49m\u001b[43m,\u001b[49m\u001b[43m \u001b[49m\u001b[38;5;241;43m*\u001b[39;49m\u001b[38;5;241;43m*\u001b[39;49m\u001b[38;5;28;43mself\u001b[39;49m\u001b[38;5;241;43m.\u001b[39;49m\u001b[43mkwargs\u001b[49m\u001b[43m)\u001b[49m\n\u001b[1;32m     59\u001b[0m \u001b[38;5;28;01mexcept\u001b[39;00m \u001b[38;5;167;01mBaseException\u001b[39;00m \u001b[38;5;28;01mas\u001b[39;00m exc:\n",
      "File \u001b[0;32m~/anaconda3/lib/python3.10/socket.py:955\u001b[0m, in \u001b[0;36mgetaddrinfo\u001b[0;34m(host, port, family, type, proto, flags)\u001b[0m\n\u001b[1;32m    954\u001b[0m addrlist \u001b[38;5;241m=\u001b[39m []\n\u001b[0;32m--> 955\u001b[0m \u001b[38;5;28;01mfor\u001b[39;00m res \u001b[38;5;129;01min\u001b[39;00m \u001b[43m_socket\u001b[49m\u001b[38;5;241;43m.\u001b[39;49m\u001b[43mgetaddrinfo\u001b[49m\u001b[43m(\u001b[49m\u001b[43mhost\u001b[49m\u001b[43m,\u001b[49m\u001b[43m \u001b[49m\u001b[43mport\u001b[49m\u001b[43m,\u001b[49m\u001b[43m \u001b[49m\u001b[43mfamily\u001b[49m\u001b[43m,\u001b[49m\u001b[43m \u001b[49m\u001b[38;5;28;43mtype\u001b[39;49m\u001b[43m,\u001b[49m\u001b[43m \u001b[49m\u001b[43mproto\u001b[49m\u001b[43m,\u001b[49m\u001b[43m \u001b[49m\u001b[43mflags\u001b[49m\u001b[43m)\u001b[49m:\n\u001b[1;32m    956\u001b[0m     af, socktype, proto, canonname, sa \u001b[38;5;241m=\u001b[39m res\n",
      "\u001b[0;31mgaierror\u001b[0m: [Errno 8] nodename nor servname provided, or not known",
      "\nThe above exception was the direct cause of the following exception:\n",
      "\u001b[0;31mClientConnectorError\u001b[0m                      Traceback (most recent call last)",
      "File \u001b[0;32m~/anaconda3/lib/python3.10/site-packages/aiobotocore/httpsession.py:208\u001b[0m, in \u001b[0;36mAIOHTTPSession.send\u001b[0;34m(self, request)\u001b[0m\n\u001b[1;32m    207\u001b[0m url \u001b[38;5;241m=\u001b[39m URL(url, encoded\u001b[38;5;241m=\u001b[39m\u001b[38;5;28;01mTrue\u001b[39;00m)\n\u001b[0;32m--> 208\u001b[0m response \u001b[38;5;241m=\u001b[39m \u001b[38;5;28;01mawait\u001b[39;00m \u001b[38;5;28mself\u001b[39m\u001b[38;5;241m.\u001b[39m_session\u001b[38;5;241m.\u001b[39mrequest(\n\u001b[1;32m    209\u001b[0m     request\u001b[38;5;241m.\u001b[39mmethod,\n\u001b[1;32m    210\u001b[0m     url\u001b[38;5;241m=\u001b[39murl,\n\u001b[1;32m    211\u001b[0m     chunked\u001b[38;5;241m=\u001b[39mchunked,\n\u001b[1;32m    212\u001b[0m     headers\u001b[38;5;241m=\u001b[39mheaders_,\n\u001b[1;32m    213\u001b[0m     data\u001b[38;5;241m=\u001b[39mdata,\n\u001b[1;32m    214\u001b[0m     proxy\u001b[38;5;241m=\u001b[39mproxy_url,\n\u001b[1;32m    215\u001b[0m     proxy_headers\u001b[38;5;241m=\u001b[39mproxy_headers,\n\u001b[1;32m    216\u001b[0m )\n\u001b[1;32m    218\u001b[0m http_response \u001b[38;5;241m=\u001b[39m aiobotocore\u001b[38;5;241m.\u001b[39mawsrequest\u001b[38;5;241m.\u001b[39mAioAWSResponse(\n\u001b[1;32m    219\u001b[0m     \u001b[38;5;28mstr\u001b[39m(response\u001b[38;5;241m.\u001b[39murl), response\u001b[38;5;241m.\u001b[39mstatus, response\u001b[38;5;241m.\u001b[39mheaders, response\n\u001b[1;32m    220\u001b[0m )\n",
      "File \u001b[0;32m~/anaconda3/lib/python3.10/site-packages/aiohttp/client.py:536\u001b[0m, in \u001b[0;36mClientSession._request\u001b[0;34m(self, method, str_or_url, params, data, json, cookies, headers, skip_auto_headers, auth, allow_redirects, max_redirects, compress, chunked, expect100, raise_for_status, read_until_eof, proxy, proxy_auth, timeout, verify_ssl, fingerprint, ssl_context, ssl, proxy_headers, trace_request_ctx, read_bufsize)\u001b[0m\n\u001b[1;32m    535\u001b[0m         \u001b[38;5;28;01massert\u001b[39;00m \u001b[38;5;28mself\u001b[39m\u001b[38;5;241m.\u001b[39m_connector \u001b[38;5;129;01mis\u001b[39;00m \u001b[38;5;129;01mnot\u001b[39;00m \u001b[38;5;28;01mNone\u001b[39;00m\n\u001b[0;32m--> 536\u001b[0m         conn \u001b[38;5;241m=\u001b[39m \u001b[38;5;28;01mawait\u001b[39;00m \u001b[38;5;28mself\u001b[39m\u001b[38;5;241m.\u001b[39m_connector\u001b[38;5;241m.\u001b[39mconnect(\n\u001b[1;32m    537\u001b[0m             req, traces\u001b[38;5;241m=\u001b[39mtraces, timeout\u001b[38;5;241m=\u001b[39mreal_timeout\n\u001b[1;32m    538\u001b[0m         )\n\u001b[1;32m    539\u001b[0m \u001b[38;5;28;01mexcept\u001b[39;00m asyncio\u001b[38;5;241m.\u001b[39mTimeoutError \u001b[38;5;28;01mas\u001b[39;00m exc:\n",
      "File \u001b[0;32m~/anaconda3/lib/python3.10/site-packages/aiohttp/connector.py:540\u001b[0m, in \u001b[0;36mBaseConnector.connect\u001b[0;34m(self, req, traces, timeout)\u001b[0m\n\u001b[1;32m    539\u001b[0m \u001b[38;5;28;01mtry\u001b[39;00m:\n\u001b[0;32m--> 540\u001b[0m     proto \u001b[38;5;241m=\u001b[39m \u001b[38;5;28;01mawait\u001b[39;00m \u001b[38;5;28mself\u001b[39m\u001b[38;5;241m.\u001b[39m_create_connection(req, traces, timeout)\n\u001b[1;32m    541\u001b[0m     \u001b[38;5;28;01mif\u001b[39;00m \u001b[38;5;28mself\u001b[39m\u001b[38;5;241m.\u001b[39m_closed:\n",
      "File \u001b[0;32m~/anaconda3/lib/python3.10/site-packages/aiohttp/connector.py:901\u001b[0m, in \u001b[0;36mTCPConnector._create_connection\u001b[0;34m(self, req, traces, timeout)\u001b[0m\n\u001b[1;32m    900\u001b[0m \u001b[38;5;28;01melse\u001b[39;00m:\n\u001b[0;32m--> 901\u001b[0m     _, proto \u001b[38;5;241m=\u001b[39m \u001b[38;5;28;01mawait\u001b[39;00m \u001b[38;5;28mself\u001b[39m\u001b[38;5;241m.\u001b[39m_create_direct_connection(req, traces, timeout)\n\u001b[1;32m    903\u001b[0m \u001b[38;5;28;01mreturn\u001b[39;00m proto\n",
      "File \u001b[0;32m~/anaconda3/lib/python3.10/site-packages/aiohttp/connector.py:1166\u001b[0m, in \u001b[0;36mTCPConnector._create_direct_connection\u001b[0;34m(self, req, traces, timeout, client_error)\u001b[0m\n\u001b[1;32m   1164\u001b[0m     \u001b[38;5;66;03m# in case of proxy it is not ClientProxyConnectionError\u001b[39;00m\n\u001b[1;32m   1165\u001b[0m     \u001b[38;5;66;03m# it is problem of resolving proxy ip itself\u001b[39;00m\n\u001b[0;32m-> 1166\u001b[0m     \u001b[38;5;28;01mraise\u001b[39;00m ClientConnectorError(req\u001b[38;5;241m.\u001b[39mconnection_key, exc) \u001b[38;5;28;01mfrom\u001b[39;00m \u001b[38;5;21;01mexc\u001b[39;00m\n\u001b[1;32m   1168\u001b[0m last_exc: Optional[\u001b[38;5;167;01mException\u001b[39;00m] \u001b[38;5;241m=\u001b[39m \u001b[38;5;28;01mNone\u001b[39;00m\n",
      "\u001b[0;31mClientConnectorError\u001b[0m: Cannot connect to host asra-test-bucket.s3.ohio.amazonaws.com:443 ssl:default [nodename nor servname provided, or not known]",
      "\nDuring handling of the above exception, another exception occurred:\n",
      "\u001b[0;31mEndpointConnectionError\u001b[0m                   Traceback (most recent call last)",
      "Cell \u001b[0;32mIn[5], line 2\u001b[0m\n\u001b[1;32m      1\u001b[0m \u001b[38;5;28;01mfor\u001b[39;00m count, i \u001b[38;5;129;01min\u001b[39;00m \u001b[38;5;28menumerate\u001b[39m(consumer):\n\u001b[0;32m----> 2\u001b[0m     \u001b[38;5;28;01mwith\u001b[39;00m s3\u001b[38;5;241m.\u001b[39mopen(\u001b[38;5;124m\"\u001b[39m\u001b[38;5;124ms3://asra-test-bucket/stock_market_\u001b[39m\u001b[38;5;132;01m{}\u001b[39;00m\u001b[38;5;124m.json\u001b[39m\u001b[38;5;124m\"\u001b[39m\u001b[38;5;241m.\u001b[39mformat(count), \u001b[38;5;124m'\u001b[39m\u001b[38;5;124mw\u001b[39m\u001b[38;5;124m'\u001b[39m) \u001b[38;5;28;01mas\u001b[39;00m file:\n\u001b[1;32m      3\u001b[0m         json\u001b[38;5;241m.\u001b[39mdump(i\u001b[38;5;241m.\u001b[39mvalue, file)\n",
      "File \u001b[0;32m~/anaconda3/lib/python3.10/site-packages/fsspec/spec.py:1786\u001b[0m, in \u001b[0;36mAbstractBufferedFile.close\u001b[0;34m(self)\u001b[0m\n\u001b[1;32m   1784\u001b[0m \u001b[38;5;28;01melse\u001b[39;00m:\n\u001b[1;32m   1785\u001b[0m     \u001b[38;5;28;01mif\u001b[39;00m \u001b[38;5;129;01mnot\u001b[39;00m \u001b[38;5;28mself\u001b[39m\u001b[38;5;241m.\u001b[39mforced:\n\u001b[0;32m-> 1786\u001b[0m         \u001b[38;5;28;43mself\u001b[39;49m\u001b[38;5;241;43m.\u001b[39;49m\u001b[43mflush\u001b[49m\u001b[43m(\u001b[49m\u001b[43mforce\u001b[49m\u001b[38;5;241;43m=\u001b[39;49m\u001b[38;5;28;43;01mTrue\u001b[39;49;00m\u001b[43m)\u001b[49m\n\u001b[1;32m   1788\u001b[0m     \u001b[38;5;28;01mif\u001b[39;00m \u001b[38;5;28mself\u001b[39m\u001b[38;5;241m.\u001b[39mfs \u001b[38;5;129;01mis\u001b[39;00m \u001b[38;5;129;01mnot\u001b[39;00m \u001b[38;5;28;01mNone\u001b[39;00m:\n\u001b[1;32m   1789\u001b[0m         \u001b[38;5;28mself\u001b[39m\u001b[38;5;241m.\u001b[39mfs\u001b[38;5;241m.\u001b[39minvalidate_cache(\u001b[38;5;28mself\u001b[39m\u001b[38;5;241m.\u001b[39mpath)\n",
      "File \u001b[0;32m~/anaconda3/lib/python3.10/site-packages/fsspec/spec.py:1657\u001b[0m, in \u001b[0;36mAbstractBufferedFile.flush\u001b[0;34m(self, force)\u001b[0m\n\u001b[1;32m   1654\u001b[0m         \u001b[38;5;28mself\u001b[39m\u001b[38;5;241m.\u001b[39mclosed \u001b[38;5;241m=\u001b[39m \u001b[38;5;28;01mTrue\u001b[39;00m\n\u001b[1;32m   1655\u001b[0m         \u001b[38;5;28;01mraise\u001b[39;00m\n\u001b[0;32m-> 1657\u001b[0m \u001b[38;5;28;01mif\u001b[39;00m \u001b[38;5;28;43mself\u001b[39;49m\u001b[38;5;241;43m.\u001b[39;49m\u001b[43m_upload_chunk\u001b[49m\u001b[43m(\u001b[49m\u001b[43mfinal\u001b[49m\u001b[38;5;241;43m=\u001b[39;49m\u001b[43mforce\u001b[49m\u001b[43m)\u001b[49m \u001b[38;5;129;01mis\u001b[39;00m \u001b[38;5;129;01mnot\u001b[39;00m \u001b[38;5;28;01mFalse\u001b[39;00m:\n\u001b[1;32m   1658\u001b[0m     \u001b[38;5;28mself\u001b[39m\u001b[38;5;241m.\u001b[39moffset \u001b[38;5;241m+\u001b[39m\u001b[38;5;241m=\u001b[39m \u001b[38;5;28mself\u001b[39m\u001b[38;5;241m.\u001b[39mbuffer\u001b[38;5;241m.\u001b[39mseek(\u001b[38;5;241m0\u001b[39m, \u001b[38;5;241m2\u001b[39m)\n\u001b[1;32m   1659\u001b[0m     \u001b[38;5;28mself\u001b[39m\u001b[38;5;241m.\u001b[39mbuffer \u001b[38;5;241m=\u001b[39m io\u001b[38;5;241m.\u001b[39mBytesIO()\n",
      "File \u001b[0;32m~/anaconda3/lib/python3.10/site-packages/s3fs/core.py:2215\u001b[0m, in \u001b[0;36mS3File._upload_chunk\u001b[0;34m(self, final)\u001b[0m\n\u001b[1;32m   2212\u001b[0m     \u001b[38;5;28mself\u001b[39m\u001b[38;5;241m.\u001b[39mparts\u001b[38;5;241m.\u001b[39mappend({\u001b[38;5;124m\"\u001b[39m\u001b[38;5;124mPartNumber\u001b[39m\u001b[38;5;124m\"\u001b[39m: part, \u001b[38;5;124m\"\u001b[39m\u001b[38;5;124mETag\u001b[39m\u001b[38;5;124m\"\u001b[39m: out[\u001b[38;5;124m\"\u001b[39m\u001b[38;5;124mETag\u001b[39m\u001b[38;5;124m\"\u001b[39m]})\n\u001b[1;32m   2214\u001b[0m \u001b[38;5;28;01mif\u001b[39;00m \u001b[38;5;28mself\u001b[39m\u001b[38;5;241m.\u001b[39mautocommit \u001b[38;5;129;01mand\u001b[39;00m final:\n\u001b[0;32m-> 2215\u001b[0m     \u001b[38;5;28;43mself\u001b[39;49m\u001b[38;5;241;43m.\u001b[39;49m\u001b[43mcommit\u001b[49m\u001b[43m(\u001b[49m\u001b[43m)\u001b[49m\n\u001b[1;32m   2216\u001b[0m \u001b[38;5;28;01mreturn\u001b[39;00m \u001b[38;5;129;01mnot\u001b[39;00m final\n",
      "File \u001b[0;32m~/anaconda3/lib/python3.10/site-packages/s3fs/core.py:2230\u001b[0m, in \u001b[0;36mS3File.commit\u001b[0;34m(self)\u001b[0m\n\u001b[1;32m   2228\u001b[0m     \u001b[38;5;28mself\u001b[39m\u001b[38;5;241m.\u001b[39mbuffer\u001b[38;5;241m.\u001b[39mseek(\u001b[38;5;241m0\u001b[39m)\n\u001b[1;32m   2229\u001b[0m     data \u001b[38;5;241m=\u001b[39m \u001b[38;5;28mself\u001b[39m\u001b[38;5;241m.\u001b[39mbuffer\u001b[38;5;241m.\u001b[39mread()\n\u001b[0;32m-> 2230\u001b[0m     write_result \u001b[38;5;241m=\u001b[39m \u001b[38;5;28;43mself\u001b[39;49m\u001b[38;5;241;43m.\u001b[39;49m\u001b[43m_call_s3\u001b[49m\u001b[43m(\u001b[49m\n\u001b[1;32m   2231\u001b[0m \u001b[43m        \u001b[49m\u001b[38;5;124;43m\"\u001b[39;49m\u001b[38;5;124;43mput_object\u001b[39;49m\u001b[38;5;124;43m\"\u001b[39;49m\u001b[43m,\u001b[49m\n\u001b[1;32m   2232\u001b[0m \u001b[43m        \u001b[49m\u001b[43mKey\u001b[49m\u001b[38;5;241;43m=\u001b[39;49m\u001b[38;5;28;43mself\u001b[39;49m\u001b[38;5;241;43m.\u001b[39;49m\u001b[43mkey\u001b[49m\u001b[43m,\u001b[49m\n\u001b[1;32m   2233\u001b[0m \u001b[43m        \u001b[49m\u001b[43mBucket\u001b[49m\u001b[38;5;241;43m=\u001b[39;49m\u001b[38;5;28;43mself\u001b[39;49m\u001b[38;5;241;43m.\u001b[39;49m\u001b[43mbucket\u001b[49m\u001b[43m,\u001b[49m\n\u001b[1;32m   2234\u001b[0m \u001b[43m        \u001b[49m\u001b[43mBody\u001b[49m\u001b[38;5;241;43m=\u001b[39;49m\u001b[43mdata\u001b[49m\u001b[43m,\u001b[49m\n\u001b[1;32m   2235\u001b[0m \u001b[43m        \u001b[49m\u001b[43mACL\u001b[49m\u001b[38;5;241;43m=\u001b[39;49m\u001b[38;5;28;43mself\u001b[39;49m\u001b[38;5;241;43m.\u001b[39;49m\u001b[43macl\u001b[49m\u001b[43m,\u001b[49m\n\u001b[1;32m   2236\u001b[0m \u001b[43m        \u001b[49m\u001b[38;5;241;43m*\u001b[39;49m\u001b[38;5;241;43m*\u001b[39;49m\u001b[38;5;28;43mself\u001b[39;49m\u001b[38;5;241;43m.\u001b[39;49m\u001b[43mkwargs\u001b[49m\u001b[43m,\u001b[49m\n\u001b[1;32m   2237\u001b[0m \u001b[43m    \u001b[49m\u001b[43m)\u001b[49m\n\u001b[1;32m   2238\u001b[0m \u001b[38;5;28;01melse\u001b[39;00m:\n\u001b[1;32m   2239\u001b[0m     \u001b[38;5;28;01mraise\u001b[39;00m \u001b[38;5;167;01mRuntimeError\u001b[39;00m\n",
      "File \u001b[0;32m~/anaconda3/lib/python3.10/site-packages/s3fs/core.py:2082\u001b[0m, in \u001b[0;36mS3File._call_s3\u001b[0;34m(self, method, *kwarglist, **kwargs)\u001b[0m\n\u001b[1;32m   2081\u001b[0m \u001b[38;5;28;01mdef\u001b[39;00m \u001b[38;5;21m_call_s3\u001b[39m(\u001b[38;5;28mself\u001b[39m, method, \u001b[38;5;241m*\u001b[39mkwarglist, \u001b[38;5;241m*\u001b[39m\u001b[38;5;241m*\u001b[39mkwargs):\n\u001b[0;32m-> 2082\u001b[0m     \u001b[38;5;28;01mreturn\u001b[39;00m \u001b[38;5;28;43mself\u001b[39;49m\u001b[38;5;241;43m.\u001b[39;49m\u001b[43mfs\u001b[49m\u001b[38;5;241;43m.\u001b[39;49m\u001b[43mcall_s3\u001b[49m\u001b[43m(\u001b[49m\u001b[43mmethod\u001b[49m\u001b[43m,\u001b[49m\u001b[43m \u001b[49m\u001b[38;5;28;43mself\u001b[39;49m\u001b[38;5;241;43m.\u001b[39;49m\u001b[43ms3_additional_kwargs\u001b[49m\u001b[43m,\u001b[49m\u001b[43m \u001b[49m\u001b[38;5;241;43m*\u001b[39;49m\u001b[43mkwarglist\u001b[49m\u001b[43m,\u001b[49m\u001b[43m \u001b[49m\u001b[38;5;241;43m*\u001b[39;49m\u001b[38;5;241;43m*\u001b[39;49m\u001b[43mkwargs\u001b[49m\u001b[43m)\u001b[49m\n",
      "File \u001b[0;32m~/anaconda3/lib/python3.10/site-packages/fsspec/asyn.py:115\u001b[0m, in \u001b[0;36msync_wrapper.<locals>.wrapper\u001b[0;34m(*args, **kwargs)\u001b[0m\n\u001b[1;32m    112\u001b[0m \u001b[38;5;129m@functools\u001b[39m\u001b[38;5;241m.\u001b[39mwraps(func)\n\u001b[1;32m    113\u001b[0m \u001b[38;5;28;01mdef\u001b[39;00m \u001b[38;5;21mwrapper\u001b[39m(\u001b[38;5;241m*\u001b[39margs, \u001b[38;5;241m*\u001b[39m\u001b[38;5;241m*\u001b[39mkwargs):\n\u001b[1;32m    114\u001b[0m     \u001b[38;5;28mself\u001b[39m \u001b[38;5;241m=\u001b[39m obj \u001b[38;5;129;01mor\u001b[39;00m args[\u001b[38;5;241m0\u001b[39m]\n\u001b[0;32m--> 115\u001b[0m     \u001b[38;5;28;01mreturn\u001b[39;00m \u001b[43msync\u001b[49m\u001b[43m(\u001b[49m\u001b[38;5;28;43mself\u001b[39;49m\u001b[38;5;241;43m.\u001b[39;49m\u001b[43mloop\u001b[49m\u001b[43m,\u001b[49m\u001b[43m \u001b[49m\u001b[43mfunc\u001b[49m\u001b[43m,\u001b[49m\u001b[43m \u001b[49m\u001b[38;5;241;43m*\u001b[39;49m\u001b[43margs\u001b[49m\u001b[43m,\u001b[49m\u001b[43m \u001b[49m\u001b[38;5;241;43m*\u001b[39;49m\u001b[38;5;241;43m*\u001b[39;49m\u001b[43mkwargs\u001b[49m\u001b[43m)\u001b[49m\n",
      "File \u001b[0;32m~/anaconda3/lib/python3.10/site-packages/fsspec/asyn.py:100\u001b[0m, in \u001b[0;36msync\u001b[0;34m(loop, func, timeout, *args, **kwargs)\u001b[0m\n\u001b[1;32m     98\u001b[0m     \u001b[38;5;28;01mraise\u001b[39;00m FSTimeoutError \u001b[38;5;28;01mfrom\u001b[39;00m \u001b[38;5;21;01mreturn_result\u001b[39;00m\n\u001b[1;32m     99\u001b[0m \u001b[38;5;28;01melif\u001b[39;00m \u001b[38;5;28misinstance\u001b[39m(return_result, \u001b[38;5;167;01mBaseException\u001b[39;00m):\n\u001b[0;32m--> 100\u001b[0m     \u001b[38;5;28;01mraise\u001b[39;00m return_result\n\u001b[1;32m    101\u001b[0m \u001b[38;5;28;01melse\u001b[39;00m:\n\u001b[1;32m    102\u001b[0m     \u001b[38;5;28;01mreturn\u001b[39;00m return_result\n",
      "File \u001b[0;32m~/anaconda3/lib/python3.10/site-packages/fsspec/asyn.py:55\u001b[0m, in \u001b[0;36m_runner\u001b[0;34m(event, coro, result, timeout)\u001b[0m\n\u001b[1;32m     53\u001b[0m     coro \u001b[38;5;241m=\u001b[39m asyncio\u001b[38;5;241m.\u001b[39mwait_for(coro, timeout\u001b[38;5;241m=\u001b[39mtimeout)\n\u001b[1;32m     54\u001b[0m \u001b[38;5;28;01mtry\u001b[39;00m:\n\u001b[0;32m---> 55\u001b[0m     result[\u001b[38;5;241m0\u001b[39m] \u001b[38;5;241m=\u001b[39m \u001b[38;5;28;01mawait\u001b[39;00m coro\n\u001b[1;32m     56\u001b[0m \u001b[38;5;28;01mexcept\u001b[39;00m \u001b[38;5;167;01mException\u001b[39;00m \u001b[38;5;28;01mas\u001b[39;00m ex:\n\u001b[1;32m     57\u001b[0m     result[\u001b[38;5;241m0\u001b[39m] \u001b[38;5;241m=\u001b[39m ex\n",
      "File \u001b[0;32m~/anaconda3/lib/python3.10/site-packages/s3fs/core.py:347\u001b[0m, in \u001b[0;36mS3FileSystem._call_s3\u001b[0;34m(self, method, *akwarglist, **kwargs)\u001b[0m\n\u001b[1;32m    345\u001b[0m logger\u001b[38;5;241m.\u001b[39mdebug(\u001b[38;5;124m\"\u001b[39m\u001b[38;5;124mCALL: \u001b[39m\u001b[38;5;132;01m%s\u001b[39;00m\u001b[38;5;124m - \u001b[39m\u001b[38;5;132;01m%s\u001b[39;00m\u001b[38;5;124m - \u001b[39m\u001b[38;5;132;01m%s\u001b[39;00m\u001b[38;5;124m\"\u001b[39m, method\u001b[38;5;241m.\u001b[39m\u001b[38;5;18m__name__\u001b[39m, akwarglist, kw2)\n\u001b[1;32m    346\u001b[0m additional_kwargs \u001b[38;5;241m=\u001b[39m \u001b[38;5;28mself\u001b[39m\u001b[38;5;241m.\u001b[39m_get_s3_method_kwargs(method, \u001b[38;5;241m*\u001b[39makwarglist, \u001b[38;5;241m*\u001b[39m\u001b[38;5;241m*\u001b[39mkwargs)\n\u001b[0;32m--> 347\u001b[0m \u001b[38;5;28;01mreturn\u001b[39;00m \u001b[38;5;28;01mawait\u001b[39;00m _error_wrapper(\n\u001b[1;32m    348\u001b[0m     method, kwargs\u001b[38;5;241m=\u001b[39madditional_kwargs, retries\u001b[38;5;241m=\u001b[39m\u001b[38;5;28mself\u001b[39m\u001b[38;5;241m.\u001b[39mretries\n\u001b[1;32m    349\u001b[0m )\n",
      "File \u001b[0;32m~/anaconda3/lib/python3.10/site-packages/s3fs/core.py:139\u001b[0m, in \u001b[0;36m_error_wrapper\u001b[0;34m(func, args, kwargs, retries)\u001b[0m\n\u001b[1;32m    137\u001b[0m         err \u001b[38;5;241m=\u001b[39m e\n\u001b[1;32m    138\u001b[0m err \u001b[38;5;241m=\u001b[39m translate_boto_error(err)\n\u001b[0;32m--> 139\u001b[0m \u001b[38;5;28;01mraise\u001b[39;00m err\n",
      "File \u001b[0;32m~/anaconda3/lib/python3.10/site-packages/s3fs/core.py:112\u001b[0m, in \u001b[0;36m_error_wrapper\u001b[0;34m(func, args, kwargs, retries)\u001b[0m\n\u001b[1;32m    110\u001b[0m \u001b[38;5;28;01mfor\u001b[39;00m i \u001b[38;5;129;01min\u001b[39;00m \u001b[38;5;28mrange\u001b[39m(retries):\n\u001b[1;32m    111\u001b[0m     \u001b[38;5;28;01mtry\u001b[39;00m:\n\u001b[0;32m--> 112\u001b[0m         \u001b[38;5;28;01mreturn\u001b[39;00m \u001b[38;5;28;01mawait\u001b[39;00m func(\u001b[38;5;241m*\u001b[39margs, \u001b[38;5;241m*\u001b[39m\u001b[38;5;241m*\u001b[39mkwargs)\n\u001b[1;32m    113\u001b[0m     \u001b[38;5;28;01mexcept\u001b[39;00m S3_RETRYABLE_ERRORS \u001b[38;5;28;01mas\u001b[39;00m e:\n\u001b[1;32m    114\u001b[0m         err \u001b[38;5;241m=\u001b[39m e\n",
      "File \u001b[0;32m~/anaconda3/lib/python3.10/site-packages/aiobotocore/client.py:341\u001b[0m, in \u001b[0;36mAioBaseClient._make_api_call\u001b[0;34m(self, operation_name, api_params)\u001b[0m\n\u001b[1;32m    339\u001b[0m \u001b[38;5;28;01melse\u001b[39;00m:\n\u001b[1;32m    340\u001b[0m     apply_request_checksum(request_dict)\n\u001b[0;32m--> 341\u001b[0m     http, parsed_response \u001b[38;5;241m=\u001b[39m \u001b[38;5;28;01mawait\u001b[39;00m \u001b[38;5;28mself\u001b[39m\u001b[38;5;241m.\u001b[39m_make_request(\n\u001b[1;32m    342\u001b[0m         operation_model, request_dict, request_context\n\u001b[1;32m    343\u001b[0m     )\n\u001b[1;32m    345\u001b[0m \u001b[38;5;28;01mawait\u001b[39;00m \u001b[38;5;28mself\u001b[39m\u001b[38;5;241m.\u001b[39mmeta\u001b[38;5;241m.\u001b[39mevents\u001b[38;5;241m.\u001b[39memit(\n\u001b[1;32m    346\u001b[0m     \u001b[38;5;124m'\u001b[39m\u001b[38;5;124mafter-call.\u001b[39m\u001b[38;5;132;01m{service_id}\u001b[39;00m\u001b[38;5;124m.\u001b[39m\u001b[38;5;132;01m{operation_name}\u001b[39;00m\u001b[38;5;124m'\u001b[39m\u001b[38;5;241m.\u001b[39mformat(\n\u001b[1;32m    347\u001b[0m         service_id\u001b[38;5;241m=\u001b[39mservice_id, operation_name\u001b[38;5;241m=\u001b[39moperation_name\n\u001b[0;32m   (...)\u001b[0m\n\u001b[1;32m    352\u001b[0m     context\u001b[38;5;241m=\u001b[39mrequest_context,\n\u001b[1;32m    353\u001b[0m )\n\u001b[1;32m    355\u001b[0m \u001b[38;5;28;01mif\u001b[39;00m http\u001b[38;5;241m.\u001b[39mstatus_code \u001b[38;5;241m>\u001b[39m\u001b[38;5;241m=\u001b[39m \u001b[38;5;241m300\u001b[39m:\n",
      "File \u001b[0;32m~/anaconda3/lib/python3.10/site-packages/aiobotocore/client.py:366\u001b[0m, in \u001b[0;36mAioBaseClient._make_request\u001b[0;34m(self, operation_model, request_dict, request_context)\u001b[0m\n\u001b[1;32m    362\u001b[0m \u001b[38;5;28;01masync\u001b[39;00m \u001b[38;5;28;01mdef\u001b[39;00m \u001b[38;5;21m_make_request\u001b[39m(\n\u001b[1;32m    363\u001b[0m     \u001b[38;5;28mself\u001b[39m, operation_model, request_dict, request_context\n\u001b[1;32m    364\u001b[0m ):\n\u001b[1;32m    365\u001b[0m     \u001b[38;5;28;01mtry\u001b[39;00m:\n\u001b[0;32m--> 366\u001b[0m         \u001b[38;5;28;01mreturn\u001b[39;00m \u001b[38;5;28;01mawait\u001b[39;00m \u001b[38;5;28mself\u001b[39m\u001b[38;5;241m.\u001b[39m_endpoint\u001b[38;5;241m.\u001b[39mmake_request(\n\u001b[1;32m    367\u001b[0m             operation_model, request_dict\n\u001b[1;32m    368\u001b[0m         )\n\u001b[1;32m    369\u001b[0m     \u001b[38;5;28;01mexcept\u001b[39;00m \u001b[38;5;167;01mException\u001b[39;00m \u001b[38;5;28;01mas\u001b[39;00m e:\n\u001b[1;32m    370\u001b[0m         \u001b[38;5;28;01mawait\u001b[39;00m \u001b[38;5;28mself\u001b[39m\u001b[38;5;241m.\u001b[39mmeta\u001b[38;5;241m.\u001b[39mevents\u001b[38;5;241m.\u001b[39memit(\n\u001b[1;32m    371\u001b[0m             \u001b[38;5;124m'\u001b[39m\u001b[38;5;124mafter-call-error.\u001b[39m\u001b[38;5;132;01m{service_id}\u001b[39;00m\u001b[38;5;124m.\u001b[39m\u001b[38;5;132;01m{operation_name}\u001b[39;00m\u001b[38;5;124m'\u001b[39m\u001b[38;5;241m.\u001b[39mformat(\n\u001b[1;32m    372\u001b[0m                 service_id\u001b[38;5;241m=\u001b[39m\u001b[38;5;28mself\u001b[39m\u001b[38;5;241m.\u001b[39m_service_model\u001b[38;5;241m.\u001b[39mservice_id\u001b[38;5;241m.\u001b[39mhyphenize(),\n\u001b[0;32m   (...)\u001b[0m\n\u001b[1;32m    376\u001b[0m             context\u001b[38;5;241m=\u001b[39mrequest_context,\n\u001b[1;32m    377\u001b[0m         )\n",
      "File \u001b[0;32m~/anaconda3/lib/python3.10/site-packages/aiobotocore/endpoint.py:100\u001b[0m, in \u001b[0;36mAioEndpoint._send_request\u001b[0;34m(self, request_dict, operation_model)\u001b[0m\n\u001b[1;32m     96\u001b[0m request \u001b[38;5;241m=\u001b[39m \u001b[38;5;28;01mawait\u001b[39;00m \u001b[38;5;28mself\u001b[39m\u001b[38;5;241m.\u001b[39mcreate_request(request_dict, operation_model)\n\u001b[1;32m     97\u001b[0m success_response, exception \u001b[38;5;241m=\u001b[39m \u001b[38;5;28;01mawait\u001b[39;00m \u001b[38;5;28mself\u001b[39m\u001b[38;5;241m.\u001b[39m_get_response(\n\u001b[1;32m     98\u001b[0m     request, operation_model, context\n\u001b[1;32m     99\u001b[0m )\n\u001b[0;32m--> 100\u001b[0m \u001b[38;5;28;01mwhile\u001b[39;00m \u001b[38;5;28;01mawait\u001b[39;00m \u001b[38;5;28mself\u001b[39m\u001b[38;5;241m.\u001b[39m_needs_retry(\n\u001b[1;32m    101\u001b[0m     attempts,\n\u001b[1;32m    102\u001b[0m     operation_model,\n\u001b[1;32m    103\u001b[0m     request_dict,\n\u001b[1;32m    104\u001b[0m     success_response,\n\u001b[1;32m    105\u001b[0m     exception,\n\u001b[1;32m    106\u001b[0m ):\n\u001b[1;32m    107\u001b[0m     attempts \u001b[38;5;241m+\u001b[39m\u001b[38;5;241m=\u001b[39m \u001b[38;5;241m1\u001b[39m\n\u001b[1;32m    108\u001b[0m     \u001b[38;5;28mself\u001b[39m\u001b[38;5;241m.\u001b[39m_update_retries_context(context, attempts, success_response)\n",
      "File \u001b[0;32m~/anaconda3/lib/python3.10/site-packages/aiobotocore/endpoint.py:262\u001b[0m, in \u001b[0;36mAioEndpoint._needs_retry\u001b[0;34m(self, attempts, operation_model, request_dict, response, caught_exception)\u001b[0m\n\u001b[1;32m    260\u001b[0m service_id \u001b[38;5;241m=\u001b[39m operation_model\u001b[38;5;241m.\u001b[39mservice_model\u001b[38;5;241m.\u001b[39mservice_id\u001b[38;5;241m.\u001b[39mhyphenize()\n\u001b[1;32m    261\u001b[0m event_name \u001b[38;5;241m=\u001b[39m \u001b[38;5;124mf\u001b[39m\u001b[38;5;124m\"\u001b[39m\u001b[38;5;124mneeds-retry.\u001b[39m\u001b[38;5;132;01m{\u001b[39;00mservice_id\u001b[38;5;132;01m}\u001b[39;00m\u001b[38;5;124m.\u001b[39m\u001b[38;5;132;01m{\u001b[39;00moperation_model\u001b[38;5;241m.\u001b[39mname\u001b[38;5;132;01m}\u001b[39;00m\u001b[38;5;124m\"\u001b[39m\n\u001b[0;32m--> 262\u001b[0m responses \u001b[38;5;241m=\u001b[39m \u001b[38;5;28;01mawait\u001b[39;00m \u001b[38;5;28mself\u001b[39m\u001b[38;5;241m.\u001b[39m_event_emitter\u001b[38;5;241m.\u001b[39memit(\n\u001b[1;32m    263\u001b[0m     event_name,\n\u001b[1;32m    264\u001b[0m     response\u001b[38;5;241m=\u001b[39mresponse,\n\u001b[1;32m    265\u001b[0m     endpoint\u001b[38;5;241m=\u001b[39m\u001b[38;5;28mself\u001b[39m,\n\u001b[1;32m    266\u001b[0m     operation\u001b[38;5;241m=\u001b[39moperation_model,\n\u001b[1;32m    267\u001b[0m     attempts\u001b[38;5;241m=\u001b[39mattempts,\n\u001b[1;32m    268\u001b[0m     caught_exception\u001b[38;5;241m=\u001b[39mcaught_exception,\n\u001b[1;32m    269\u001b[0m     request_dict\u001b[38;5;241m=\u001b[39mrequest_dict,\n\u001b[1;32m    270\u001b[0m )\n\u001b[1;32m    271\u001b[0m handler_response \u001b[38;5;241m=\u001b[39m first_non_none_response(responses)\n\u001b[1;32m    272\u001b[0m \u001b[38;5;28;01mif\u001b[39;00m handler_response \u001b[38;5;129;01mis\u001b[39;00m \u001b[38;5;28;01mNone\u001b[39;00m:\n",
      "File \u001b[0;32m~/anaconda3/lib/python3.10/site-packages/aiobotocore/hooks.py:66\u001b[0m, in \u001b[0;36mAioHierarchicalEmitter._emit\u001b[0;34m(self, event_name, kwargs, stop_on_response)\u001b[0m\n\u001b[1;32m     63\u001b[0m logger\u001b[38;5;241m.\u001b[39mdebug(\u001b[38;5;124m'\u001b[39m\u001b[38;5;124mEvent \u001b[39m\u001b[38;5;132;01m%s\u001b[39;00m\u001b[38;5;124m: calling handler \u001b[39m\u001b[38;5;132;01m%s\u001b[39;00m\u001b[38;5;124m'\u001b[39m, event_name, handler)\n\u001b[1;32m     65\u001b[0m \u001b[38;5;66;03m# Await the handler if its a coroutine.\u001b[39;00m\n\u001b[0;32m---> 66\u001b[0m response \u001b[38;5;241m=\u001b[39m \u001b[38;5;28;01mawait\u001b[39;00m resolve_awaitable(handler(\u001b[38;5;241m*\u001b[39m\u001b[38;5;241m*\u001b[39mkwargs))\n\u001b[1;32m     67\u001b[0m responses\u001b[38;5;241m.\u001b[39mappend((handler, response))\n\u001b[1;32m     68\u001b[0m \u001b[38;5;28;01mif\u001b[39;00m stop_on_response \u001b[38;5;129;01mand\u001b[39;00m response \u001b[38;5;129;01mis\u001b[39;00m \u001b[38;5;129;01mnot\u001b[39;00m \u001b[38;5;28;01mNone\u001b[39;00m:\n",
      "File \u001b[0;32m~/anaconda3/lib/python3.10/site-packages/aiobotocore/_helpers.py:15\u001b[0m, in \u001b[0;36mresolve_awaitable\u001b[0;34m(obj)\u001b[0m\n\u001b[1;32m     13\u001b[0m \u001b[38;5;28;01masync\u001b[39;00m \u001b[38;5;28;01mdef\u001b[39;00m \u001b[38;5;21mresolve_awaitable\u001b[39m(obj):\n\u001b[1;32m     14\u001b[0m     \u001b[38;5;28;01mif\u001b[39;00m inspect\u001b[38;5;241m.\u001b[39misawaitable(obj):\n\u001b[0;32m---> 15\u001b[0m         \u001b[38;5;28;01mreturn\u001b[39;00m \u001b[38;5;28;01mawait\u001b[39;00m obj\n\u001b[1;32m     17\u001b[0m     \u001b[38;5;28;01mreturn\u001b[39;00m obj\n",
      "File \u001b[0;32m~/anaconda3/lib/python3.10/site-packages/aiobotocore/retryhandler.py:107\u001b[0m, in \u001b[0;36mAioRetryHandler._call\u001b[0;34m(self, attempts, response, caught_exception, **kwargs)\u001b[0m\n\u001b[1;32m    104\u001b[0m     retries_context \u001b[38;5;241m=\u001b[39m kwargs[\u001b[38;5;124m'\u001b[39m\u001b[38;5;124mrequest_dict\u001b[39m\u001b[38;5;124m'\u001b[39m][\u001b[38;5;124m'\u001b[39m\u001b[38;5;124mcontext\u001b[39m\u001b[38;5;124m'\u001b[39m]\u001b[38;5;241m.\u001b[39mget(\u001b[38;5;124m'\u001b[39m\u001b[38;5;124mretries\u001b[39m\u001b[38;5;124m'\u001b[39m)\n\u001b[1;32m    105\u001b[0m     checker_kwargs\u001b[38;5;241m.\u001b[39mupdate({\u001b[38;5;124m'\u001b[39m\u001b[38;5;124mretries_context\u001b[39m\u001b[38;5;124m'\u001b[39m: retries_context})\n\u001b[0;32m--> 107\u001b[0m \u001b[38;5;28;01mif\u001b[39;00m \u001b[38;5;28;01mawait\u001b[39;00m resolve_awaitable(\u001b[38;5;28mself\u001b[39m\u001b[38;5;241m.\u001b[39m_checker(\u001b[38;5;241m*\u001b[39m\u001b[38;5;241m*\u001b[39mchecker_kwargs)):\n\u001b[1;32m    108\u001b[0m     result \u001b[38;5;241m=\u001b[39m \u001b[38;5;28mself\u001b[39m\u001b[38;5;241m.\u001b[39m_action(attempts\u001b[38;5;241m=\u001b[39mattempts)\n\u001b[1;32m    109\u001b[0m     logger\u001b[38;5;241m.\u001b[39mdebug(\u001b[38;5;124m\"\u001b[39m\u001b[38;5;124mRetry needed, action of: \u001b[39m\u001b[38;5;132;01m%s\u001b[39;00m\u001b[38;5;124m\"\u001b[39m, result)\n",
      "File \u001b[0;32m~/anaconda3/lib/python3.10/site-packages/aiobotocore/_helpers.py:15\u001b[0m, in \u001b[0;36mresolve_awaitable\u001b[0;34m(obj)\u001b[0m\n\u001b[1;32m     13\u001b[0m \u001b[38;5;28;01masync\u001b[39;00m \u001b[38;5;28;01mdef\u001b[39;00m \u001b[38;5;21mresolve_awaitable\u001b[39m(obj):\n\u001b[1;32m     14\u001b[0m     \u001b[38;5;28;01mif\u001b[39;00m inspect\u001b[38;5;241m.\u001b[39misawaitable(obj):\n\u001b[0;32m---> 15\u001b[0m         \u001b[38;5;28;01mreturn\u001b[39;00m \u001b[38;5;28;01mawait\u001b[39;00m obj\n\u001b[1;32m     17\u001b[0m     \u001b[38;5;28;01mreturn\u001b[39;00m obj\n",
      "File \u001b[0;32m~/anaconda3/lib/python3.10/site-packages/aiobotocore/retryhandler.py:126\u001b[0m, in \u001b[0;36mAioMaxAttemptsDecorator._call\u001b[0;34m(self, attempt_number, response, caught_exception, retries_context)\u001b[0m\n\u001b[1;32m    121\u001b[0m \u001b[38;5;28;01mif\u001b[39;00m retries_context:\n\u001b[1;32m    122\u001b[0m     retries_context[\u001b[38;5;124m'\u001b[39m\u001b[38;5;124mmax\u001b[39m\u001b[38;5;124m'\u001b[39m] \u001b[38;5;241m=\u001b[39m \u001b[38;5;28mmax\u001b[39m(\n\u001b[1;32m    123\u001b[0m         retries_context\u001b[38;5;241m.\u001b[39mget(\u001b[38;5;124m'\u001b[39m\u001b[38;5;124mmax\u001b[39m\u001b[38;5;124m'\u001b[39m, \u001b[38;5;241m0\u001b[39m), \u001b[38;5;28mself\u001b[39m\u001b[38;5;241m.\u001b[39m_max_attempts\n\u001b[1;32m    124\u001b[0m     )\n\u001b[0;32m--> 126\u001b[0m should_retry \u001b[38;5;241m=\u001b[39m \u001b[38;5;28;01mawait\u001b[39;00m \u001b[38;5;28mself\u001b[39m\u001b[38;5;241m.\u001b[39m_should_retry(\n\u001b[1;32m    127\u001b[0m     attempt_number, response, caught_exception\n\u001b[1;32m    128\u001b[0m )\n\u001b[1;32m    129\u001b[0m \u001b[38;5;28;01mif\u001b[39;00m should_retry:\n\u001b[1;32m    130\u001b[0m     \u001b[38;5;28;01mif\u001b[39;00m attempt_number \u001b[38;5;241m>\u001b[39m\u001b[38;5;241m=\u001b[39m \u001b[38;5;28mself\u001b[39m\u001b[38;5;241m.\u001b[39m_max_attempts:\n\u001b[1;32m    131\u001b[0m         \u001b[38;5;66;03m# explicitly set MaxAttemptsReached\u001b[39;00m\n",
      "File \u001b[0;32m~/anaconda3/lib/python3.10/site-packages/aiobotocore/retryhandler.py:165\u001b[0m, in \u001b[0;36mAioMaxAttemptsDecorator._should_retry\u001b[0;34m(self, attempt_number, response, caught_exception)\u001b[0m\n\u001b[1;32m    161\u001b[0m         \u001b[38;5;28;01mreturn\u001b[39;00m \u001b[38;5;28;01mTrue\u001b[39;00m\n\u001b[1;32m    162\u001b[0m \u001b[38;5;28;01melse\u001b[39;00m:\n\u001b[1;32m    163\u001b[0m     \u001b[38;5;66;03m# If we've exceeded the max attempts we just let the exception\u001b[39;00m\n\u001b[1;32m    164\u001b[0m     \u001b[38;5;66;03m# propagate if one has occurred.\u001b[39;00m\n\u001b[0;32m--> 165\u001b[0m     \u001b[38;5;28;01mreturn\u001b[39;00m \u001b[38;5;28;01mawait\u001b[39;00m resolve_awaitable(\n\u001b[1;32m    166\u001b[0m         \u001b[38;5;28mself\u001b[39m\u001b[38;5;241m.\u001b[39m_checker(attempt_number, response, caught_exception)\n\u001b[1;32m    167\u001b[0m     )\n",
      "File \u001b[0;32m~/anaconda3/lib/python3.10/site-packages/aiobotocore/_helpers.py:15\u001b[0m, in \u001b[0;36mresolve_awaitable\u001b[0;34m(obj)\u001b[0m\n\u001b[1;32m     13\u001b[0m \u001b[38;5;28;01masync\u001b[39;00m \u001b[38;5;28;01mdef\u001b[39;00m \u001b[38;5;21mresolve_awaitable\u001b[39m(obj):\n\u001b[1;32m     14\u001b[0m     \u001b[38;5;28;01mif\u001b[39;00m inspect\u001b[38;5;241m.\u001b[39misawaitable(obj):\n\u001b[0;32m---> 15\u001b[0m         \u001b[38;5;28;01mreturn\u001b[39;00m \u001b[38;5;28;01mawait\u001b[39;00m obj\n\u001b[1;32m     17\u001b[0m     \u001b[38;5;28;01mreturn\u001b[39;00m obj\n",
      "File \u001b[0;32m~/anaconda3/lib/python3.10/site-packages/aiobotocore/retryhandler.py:174\u001b[0m, in \u001b[0;36mAioMultiChecker._call\u001b[0;34m(self, attempt_number, response, caught_exception)\u001b[0m\n\u001b[1;32m    171\u001b[0m \u001b[38;5;28;01masync\u001b[39;00m \u001b[38;5;28;01mdef\u001b[39;00m \u001b[38;5;21m_call\u001b[39m(\u001b[38;5;28mself\u001b[39m, attempt_number, response, caught_exception):\n\u001b[1;32m    172\u001b[0m     \u001b[38;5;28;01mfor\u001b[39;00m checker \u001b[38;5;129;01min\u001b[39;00m \u001b[38;5;28mself\u001b[39m\u001b[38;5;241m.\u001b[39m_checkers:\n\u001b[1;32m    173\u001b[0m         checker_response \u001b[38;5;241m=\u001b[39m \u001b[38;5;28;01mawait\u001b[39;00m resolve_awaitable(\n\u001b[0;32m--> 174\u001b[0m             \u001b[43mchecker\u001b[49m\u001b[43m(\u001b[49m\u001b[43mattempt_number\u001b[49m\u001b[43m,\u001b[49m\u001b[43m \u001b[49m\u001b[43mresponse\u001b[49m\u001b[43m,\u001b[49m\u001b[43m \u001b[49m\u001b[43mcaught_exception\u001b[49m\u001b[43m)\u001b[49m\n\u001b[1;32m    175\u001b[0m         )\n\u001b[1;32m    176\u001b[0m         \u001b[38;5;28;01mif\u001b[39;00m checker_response:\n\u001b[1;32m    177\u001b[0m             \u001b[38;5;28;01mreturn\u001b[39;00m checker_response\n",
      "File \u001b[0;32m~/anaconda3/lib/python3.10/site-packages/botocore/retryhandler.py:247\u001b[0m, in \u001b[0;36mBaseChecker.__call__\u001b[0;34m(self, attempt_number, response, caught_exception)\u001b[0m\n\u001b[1;32m    245\u001b[0m     \u001b[38;5;28;01mreturn\u001b[39;00m \u001b[38;5;28mself\u001b[39m\u001b[38;5;241m.\u001b[39m_check_response(attempt_number, response)\n\u001b[1;32m    246\u001b[0m \u001b[38;5;28;01melif\u001b[39;00m caught_exception \u001b[38;5;129;01mis\u001b[39;00m \u001b[38;5;129;01mnot\u001b[39;00m \u001b[38;5;28;01mNone\u001b[39;00m:\n\u001b[0;32m--> 247\u001b[0m     \u001b[38;5;28;01mreturn\u001b[39;00m \u001b[38;5;28;43mself\u001b[39;49m\u001b[38;5;241;43m.\u001b[39;49m\u001b[43m_check_caught_exception\u001b[49m\u001b[43m(\u001b[49m\n\u001b[1;32m    248\u001b[0m \u001b[43m        \u001b[49m\u001b[43mattempt_number\u001b[49m\u001b[43m,\u001b[49m\u001b[43m \u001b[49m\u001b[43mcaught_exception\u001b[49m\n\u001b[1;32m    249\u001b[0m \u001b[43m    \u001b[49m\u001b[43m)\u001b[49m\n\u001b[1;32m    250\u001b[0m \u001b[38;5;28;01melse\u001b[39;00m:\n\u001b[1;32m    251\u001b[0m     \u001b[38;5;28;01mraise\u001b[39;00m \u001b[38;5;167;01mValueError\u001b[39;00m(\u001b[38;5;124m\"\u001b[39m\u001b[38;5;124mBoth response and caught_exception are None.\u001b[39m\u001b[38;5;124m\"\u001b[39m)\n",
      "File \u001b[0;32m~/anaconda3/lib/python3.10/site-packages/botocore/retryhandler.py:416\u001b[0m, in \u001b[0;36mExceptionRaiser._check_caught_exception\u001b[0;34m(self, attempt_number, caught_exception)\u001b[0m\n\u001b[1;32m    408\u001b[0m \u001b[38;5;28;01mdef\u001b[39;00m \u001b[38;5;21m_check_caught_exception\u001b[39m(\u001b[38;5;28mself\u001b[39m, attempt_number, caught_exception):\n\u001b[1;32m    409\u001b[0m     \u001b[38;5;66;03m# This is implementation specific, but this class is useful by\u001b[39;00m\n\u001b[1;32m    410\u001b[0m     \u001b[38;5;66;03m# coordinating with the MaxAttemptsDecorator.\u001b[39;00m\n\u001b[0;32m   (...)\u001b[0m\n\u001b[1;32m    414\u001b[0m     \u001b[38;5;66;03m# the MaxAttemptsDecorator is not interested in retrying the exception\u001b[39;00m\n\u001b[1;32m    415\u001b[0m     \u001b[38;5;66;03m# then this exception just propogates out past the retry code.\u001b[39;00m\n\u001b[0;32m--> 416\u001b[0m     \u001b[38;5;28;01mraise\u001b[39;00m caught_exception\n",
      "File \u001b[0;32m~/anaconda3/lib/python3.10/site-packages/aiobotocore/endpoint.py:181\u001b[0m, in \u001b[0;36mAioEndpoint._do_get_response\u001b[0;34m(self, request, operation_model, context)\u001b[0m\n\u001b[1;32m    179\u001b[0m     http_response \u001b[38;5;241m=\u001b[39m first_non_none_response(responses)\n\u001b[1;32m    180\u001b[0m     \u001b[38;5;28;01mif\u001b[39;00m http_response \u001b[38;5;129;01mis\u001b[39;00m \u001b[38;5;28;01mNone\u001b[39;00m:\n\u001b[0;32m--> 181\u001b[0m         http_response \u001b[38;5;241m=\u001b[39m \u001b[38;5;28;01mawait\u001b[39;00m \u001b[38;5;28mself\u001b[39m\u001b[38;5;241m.\u001b[39m_send(request)\n\u001b[1;32m    182\u001b[0m \u001b[38;5;28;01mexcept\u001b[39;00m HTTPClientError \u001b[38;5;28;01mas\u001b[39;00m e:\n\u001b[1;32m    183\u001b[0m     \u001b[38;5;28;01mreturn\u001b[39;00m (\u001b[38;5;28;01mNone\u001b[39;00m, e)\n",
      "File \u001b[0;32m~/anaconda3/lib/python3.10/site-packages/aiobotocore/endpoint.py:285\u001b[0m, in \u001b[0;36mAioEndpoint._send\u001b[0;34m(self, request)\u001b[0m\n\u001b[1;32m    284\u001b[0m \u001b[38;5;28;01masync\u001b[39;00m \u001b[38;5;28;01mdef\u001b[39;00m \u001b[38;5;21m_send\u001b[39m(\u001b[38;5;28mself\u001b[39m, request):\n\u001b[0;32m--> 285\u001b[0m     \u001b[38;5;28;01mreturn\u001b[39;00m \u001b[38;5;28;01mawait\u001b[39;00m \u001b[38;5;28mself\u001b[39m\u001b[38;5;241m.\u001b[39mhttp_session\u001b[38;5;241m.\u001b[39msend(request)\n",
      "File \u001b[0;32m~/anaconda3/lib/python3.10/site-packages/aiobotocore/httpsession.py:253\u001b[0m, in \u001b[0;36mAIOHTTPSession.send\u001b[0;34m(self, request)\u001b[0m\n\u001b[1;32m    247\u001b[0m         \u001b[38;5;28;01mraise\u001b[39;00m ReadTimeoutError(endpoint_url\u001b[38;5;241m=\u001b[39mrequest\u001b[38;5;241m.\u001b[39murl, error\u001b[38;5;241m=\u001b[39me)\n\u001b[1;32m    248\u001b[0m \u001b[38;5;28;01mexcept\u001b[39;00m (\n\u001b[1;32m    249\u001b[0m     ClientConnectorError,\n\u001b[1;32m    250\u001b[0m     ClientConnectionError,\n\u001b[1;32m    251\u001b[0m     socket\u001b[38;5;241m.\u001b[39mgaierror,\n\u001b[1;32m    252\u001b[0m ) \u001b[38;5;28;01mas\u001b[39;00m e:\n\u001b[0;32m--> 253\u001b[0m     \u001b[38;5;28;01mraise\u001b[39;00m EndpointConnectionError(endpoint_url\u001b[38;5;241m=\u001b[39mrequest\u001b[38;5;241m.\u001b[39murl, error\u001b[38;5;241m=\u001b[39me)\n\u001b[1;32m    254\u001b[0m \u001b[38;5;28;01mexcept\u001b[39;00m asyncio\u001b[38;5;241m.\u001b[39mTimeoutError \u001b[38;5;28;01mas\u001b[39;00m e:\n\u001b[1;32m    255\u001b[0m     \u001b[38;5;28;01mraise\u001b[39;00m ReadTimeoutError(endpoint_url\u001b[38;5;241m=\u001b[39mrequest\u001b[38;5;241m.\u001b[39murl, error\u001b[38;5;241m=\u001b[39me)\n",
      "\u001b[0;31mEndpointConnectionError\u001b[0m: Could not connect to the endpoint URL: \"https://asra-test-bucket.s3.ohio.amazonaws.com/stock_market_0.json\""
     ]
    }
   ],
   "source": [
    "for count, i in enumerate(consumer):\n",
    "    with s3.open(\"s3://asra-test-bucket/stock_market_{}.json\".format(count), 'w') as file:\n",
    "        json.dump(i.value, file)    "
   ]
  },
  {
   "cell_type": "code",
   "execution_count": null,
   "id": "7b811cb6",
   "metadata": {},
   "outputs": [],
   "source": []
  },
  {
   "cell_type": "code",
   "execution_count": null,
   "id": "c13a13b3",
   "metadata": {},
   "outputs": [],
   "source": []
  }
 ],
 "metadata": {
  "kernelspec": {
   "display_name": "Python 3 (ipykernel)",
   "language": "python",
   "name": "python3"
  },
  "language_info": {
   "codemirror_mode": {
    "name": "ipython",
    "version": 3
   },
   "file_extension": ".py",
   "mimetype": "text/x-python",
   "name": "python",
   "nbconvert_exporter": "python",
   "pygments_lexer": "ipython3",
   "version": "3.10.9"
  }
 },
 "nbformat": 4,
 "nbformat_minor": 5
}
